2020-11-09 01:01:40,122 - app - ERROR - Exception on /config/getuser [GET]
Traceback (most recent call last):
  File "/usr/local/lib/python3.9/site-packages/flask/app.py", line 2447, in wsgi_app
    response = self.full_dispatch_request()
  File "/usr/local/lib/python3.9/site-packages/flask/app.py", line 1953, in full_dispatch_request
    return self.finalize_request(rv)
  File "/usr/local/lib/python3.9/site-packages/flask/app.py", line 1970, in finalize_request
    response = self.process_response(response)
  File "/usr/local/lib/python3.9/site-packages/flask/app.py", line 2267, in process_response
    response = handler(response)
  File "/home/server/app.py", line 95, in after_request
    refresh_token = request.args['refresh_token']
  File "/usr/local/lib/python3.9/site-packages/werkzeug/datastructures.py", line 442, in __getitem__
    raise exceptions.BadRequestKeyError(key)
werkzeug.exceptions.BadRequestKeyError: 400 Bad Request: The browser (or proxy) sent a request that this server could not understand.
2020-11-09 01:01:40,123 - app - ERROR - Request finalizing failed with an error while handling an error
Traceback (most recent call last):
  File "/usr/local/lib/python3.9/site-packages/flask/app.py", line 2447, in wsgi_app
    response = self.full_dispatch_request()
  File "/usr/local/lib/python3.9/site-packages/flask/app.py", line 1953, in full_dispatch_request
    return self.finalize_request(rv)
  File "/usr/local/lib/python3.9/site-packages/flask/app.py", line 1970, in finalize_request
    response = self.process_response(response)
  File "/usr/local/lib/python3.9/site-packages/flask/app.py", line 2267, in process_response
    response = handler(response)
  File "/home/server/app.py", line 95, in after_request
    refresh_token = request.args['refresh_token']
  File "/usr/local/lib/python3.9/site-packages/werkzeug/datastructures.py", line 442, in __getitem__
    raise exceptions.BadRequestKeyError(key)
werkzeug.exceptions.BadRequestKeyError: 400 Bad Request: The browser (or proxy) sent a request that this server could not understand.

During handling of the above exception, another exception occurred:

Traceback (most recent call last):
  File "/usr/local/lib/python3.9/site-packages/flask/app.py", line 1970, in finalize_request
    response = self.process_response(response)
  File "/usr/local/lib/python3.9/site-packages/flask/app.py", line 2267, in process_response
    response = handler(response)
  File "/home/server/app.py", line 95, in after_request
    refresh_token = request.args['refresh_token']
  File "/usr/local/lib/python3.9/site-packages/werkzeug/datastructures.py", line 442, in __getitem__
    raise exceptions.BadRequestKeyError(key)
werkzeug.exceptions.BadRequestKeyError: 400 Bad Request: The browser (or proxy) sent a request that this server could not understand.
2020-11-09 01:01:40,124 - app - ERROR - ('---------------------------------每一个请求之后运行，即使遇到了异常', <BadRequestKeyError '400: Bad Request'>)
2020-11-09 01:19:21,183 - app - ERROR - Exception on /GponForm/diag_Form [POST]
Traceback (most recent call last):
  File "/usr/local/lib/python3.9/site-packages/flask/app.py", line 2447, in wsgi_app
    response = self.full_dispatch_request()
  File "/usr/local/lib/python3.9/site-packages/flask/app.py", line 1953, in full_dispatch_request
    return self.finalize_request(rv)
  File "/usr/local/lib/python3.9/site-packages/flask/app.py", line 1970, in finalize_request
    response = self.process_response(response)
  File "/usr/local/lib/python3.9/site-packages/flask/app.py", line 2267, in process_response
    response = handler(response)
  File "/home/server/app.py", line 95, in after_request
    refresh_token = request.args['refresh_token']
  File "/usr/local/lib/python3.9/site-packages/werkzeug/datastructures.py", line 442, in __getitem__
    raise exceptions.BadRequestKeyError(key)
werkzeug.exceptions.BadRequestKeyError: 400 Bad Request: The browser (or proxy) sent a request that this server could not understand.
2020-11-09 01:19:21,184 - app - ERROR - Request finalizing failed with an error while handling an error
Traceback (most recent call last):
  File "/usr/local/lib/python3.9/site-packages/flask/app.py", line 2447, in wsgi_app
    response = self.full_dispatch_request()
  File "/usr/local/lib/python3.9/site-packages/flask/app.py", line 1953, in full_dispatch_request
    return self.finalize_request(rv)
  File "/usr/local/lib/python3.9/site-packages/flask/app.py", line 1970, in finalize_request
    response = self.process_response(response)
  File "/usr/local/lib/python3.9/site-packages/flask/app.py", line 2267, in process_response
    response = handler(response)
  File "/home/server/app.py", line 95, in after_request
    refresh_token = request.args['refresh_token']
  File "/usr/local/lib/python3.9/site-packages/werkzeug/datastructures.py", line 442, in __getitem__
    raise exceptions.BadRequestKeyError(key)
werkzeug.exceptions.BadRequestKeyError: 400 Bad Request: The browser (or proxy) sent a request that this server could not understand.

During handling of the above exception, another exception occurred:

Traceback (most recent call last):
  File "/usr/local/lib/python3.9/site-packages/flask/app.py", line 1970, in finalize_request
    response = self.process_response(response)
  File "/usr/local/lib/python3.9/site-packages/flask/app.py", line 2267, in process_response
    response = handler(response)
  File "/home/server/app.py", line 95, in after_request
    refresh_token = request.args['refresh_token']
  File "/usr/local/lib/python3.9/site-packages/werkzeug/datastructures.py", line 442, in __getitem__
    raise exceptions.BadRequestKeyError(key)
werkzeug.exceptions.BadRequestKeyError: 400 Bad Request: The browser (or proxy) sent a request that this server could not understand.
2020-11-09 01:19:21,184 - app - ERROR - ('---------------------------------每一个请求之后运行，即使遇到了异常', <BadRequestKeyError '400: Bad Request'>)
2020-11-09 01:33:35,508 - app - ERROR - Exception on /currentsetting.htm [GET]
Traceback (most recent call last):
  File "/usr/local/lib/python3.9/site-packages/flask/app.py", line 2447, in wsgi_app
    response = self.full_dispatch_request()
  File "/usr/local/lib/python3.9/site-packages/flask/app.py", line 1953, in full_dispatch_request
    return self.finalize_request(rv)
  File "/usr/local/lib/python3.9/site-packages/flask/app.py", line 1970, in finalize_request
    response = self.process_response(response)
  File "/usr/local/lib/python3.9/site-packages/flask/app.py", line 2267, in process_response
    response = handler(response)
  File "/home/server/app.py", line 95, in after_request
    refresh_token = request.args['refresh_token']
  File "/usr/local/lib/python3.9/site-packages/werkzeug/datastructures.py", line 442, in __getitem__
    raise exceptions.BadRequestKeyError(key)
werkzeug.exceptions.BadRequestKeyError: 400 Bad Request: The browser (or proxy) sent a request that this server could not understand.
2020-11-09 01:33:35,508 - app - ERROR - Request finalizing failed with an error while handling an error
Traceback (most recent call last):
  File "/usr/local/lib/python3.9/site-packages/flask/app.py", line 2447, in wsgi_app
    response = self.full_dispatch_request()
  File "/usr/local/lib/python3.9/site-packages/flask/app.py", line 1953, in full_dispatch_request
    return self.finalize_request(rv)
  File "/usr/local/lib/python3.9/site-packages/flask/app.py", line 1970, in finalize_request
    response = self.process_response(response)
  File "/usr/local/lib/python3.9/site-packages/flask/app.py", line 2267, in process_response
    response = handler(response)
  File "/home/server/app.py", line 95, in after_request
    refresh_token = request.args['refresh_token']
  File "/usr/local/lib/python3.9/site-packages/werkzeug/datastructures.py", line 442, in __getitem__
    raise exceptions.BadRequestKeyError(key)
werkzeug.exceptions.BadRequestKeyError: 400 Bad Request: The browser (or proxy) sent a request that this server could not understand.

During handling of the above exception, another exception occurred:

Traceback (most recent call last):
  File "/usr/local/lib/python3.9/site-packages/flask/app.py", line 1970, in finalize_request
    response = self.process_response(response)
  File "/usr/local/lib/python3.9/site-packages/flask/app.py", line 2267, in process_response
    response = handler(response)
  File "/home/server/app.py", line 95, in after_request
    refresh_token = request.args['refresh_token']
  File "/usr/local/lib/python3.9/site-packages/werkzeug/datastructures.py", line 442, in __getitem__
    raise exceptions.BadRequestKeyError(key)
werkzeug.exceptions.BadRequestKeyError: 400 Bad Request: The browser (or proxy) sent a request that this server could not understand.
2020-11-09 01:33:35,508 - app - ERROR - ('---------------------------------每一个请求之后运行，即使遇到了异常', <BadRequestKeyError '400: Bad Request'>)
2020-11-09 02:45:44,145 - app - ERROR - Exception on /cache/global/img/gs.gif [GET]
Traceback (most recent call last):
  File "/usr/local/lib/python3.9/site-packages/flask/app.py", line 2447, in wsgi_app
    response = self.full_dispatch_request()
  File "/usr/local/lib/python3.9/site-packages/flask/app.py", line 1953, in full_dispatch_request
    return self.finalize_request(rv)
  File "/usr/local/lib/python3.9/site-packages/flask/app.py", line 1970, in finalize_request
    response = self.process_response(response)
  File "/usr/local/lib/python3.9/site-packages/flask/app.py", line 2267, in process_response
    response = handler(response)
  File "/home/server/app.py", line 95, in after_request
    refresh_token = request.args['refresh_token']
  File "/usr/local/lib/python3.9/site-packages/werkzeug/datastructures.py", line 442, in __getitem__
    raise exceptions.BadRequestKeyError(key)
werkzeug.exceptions.BadRequestKeyError: 400 Bad Request: The browser (or proxy) sent a request that this server could not understand.
2020-11-09 02:45:44,146 - app - ERROR - Request finalizing failed with an error while handling an error
Traceback (most recent call last):
  File "/usr/local/lib/python3.9/site-packages/flask/app.py", line 2447, in wsgi_app
    response = self.full_dispatch_request()
  File "/usr/local/lib/python3.9/site-packages/flask/app.py", line 1953, in full_dispatch_request
    return self.finalize_request(rv)
  File "/usr/local/lib/python3.9/site-packages/flask/app.py", line 1970, in finalize_request
    response = self.process_response(response)
  File "/usr/local/lib/python3.9/site-packages/flask/app.py", line 2267, in process_response
    response = handler(response)
  File "/home/server/app.py", line 95, in after_request
    refresh_token = request.args['refresh_token']
  File "/usr/local/lib/python3.9/site-packages/werkzeug/datastructures.py", line 442, in __getitem__
    raise exceptions.BadRequestKeyError(key)
werkzeug.exceptions.BadRequestKeyError: 400 Bad Request: The browser (or proxy) sent a request that this server could not understand.

During handling of the above exception, another exception occurred:

Traceback (most recent call last):
  File "/usr/local/lib/python3.9/site-packages/flask/app.py", line 1970, in finalize_request
    response = self.process_response(response)
  File "/usr/local/lib/python3.9/site-packages/flask/app.py", line 2267, in process_response
    response = handler(response)
  File "/home/server/app.py", line 95, in after_request
    refresh_token = request.args['refresh_token']
  File "/usr/local/lib/python3.9/site-packages/werkzeug/datastructures.py", line 442, in __getitem__
    raise exceptions.BadRequestKeyError(key)
werkzeug.exceptions.BadRequestKeyError: 400 Bad Request: The browser (or proxy) sent a request that this server could not understand.
2020-11-09 02:45:44,147 - app - ERROR - ('---------------------------------每一个请求之后运行，即使遇到了异常', <BadRequestKeyError '400: Bad Request'>)
2020-11-09 05:55:00,605 - app - ERROR - Exception on /get_user_info [POST]
Traceback (most recent call last):
  File "/usr/local/lib/python3.9/site-packages/flask/app.py", line 2447, in wsgi_app
    response = self.full_dispatch_request()
  File "/usr/local/lib/python3.9/site-packages/flask/app.py", line 1953, in full_dispatch_request
    return self.finalize_request(rv)
  File "/usr/local/lib/python3.9/site-packages/flask/app.py", line 1970, in finalize_request
    response = self.process_response(response)
  File "/usr/local/lib/python3.9/site-packages/flask/app.py", line 2267, in process_response
    response = handler(response)
  File "/home/server/app.py", line 160, in after_request
    refresh_token = request.args['refresh_token']
  File "/usr/local/lib/python3.9/site-packages/werkzeug/datastructures.py", line 442, in __getitem__
    raise exceptions.BadRequestKeyError(key)
werkzeug.exceptions.BadRequestKeyError: 400 Bad Request: The browser (or proxy) sent a request that this server could not understand.
2020-11-09 05:55:00,607 - app - ERROR - Request finalizing failed with an error while handling an error
Traceback (most recent call last):
  File "/usr/local/lib/python3.9/site-packages/flask/app.py", line 2447, in wsgi_app
    response = self.full_dispatch_request()
  File "/usr/local/lib/python3.9/site-packages/flask/app.py", line 1953, in full_dispatch_request
    return self.finalize_request(rv)
  File "/usr/local/lib/python3.9/site-packages/flask/app.py", line 1970, in finalize_request
    response = self.process_response(response)
  File "/usr/local/lib/python3.9/site-packages/flask/app.py", line 2267, in process_response
    response = handler(response)
  File "/home/server/app.py", line 160, in after_request
    refresh_token = request.args['refresh_token']
  File "/usr/local/lib/python3.9/site-packages/werkzeug/datastructures.py", line 442, in __getitem__
    raise exceptions.BadRequestKeyError(key)
werkzeug.exceptions.BadRequestKeyError: 400 Bad Request: The browser (or proxy) sent a request that this server could not understand.

During handling of the above exception, another exception occurred:

Traceback (most recent call last):
  File "/usr/local/lib/python3.9/site-packages/flask/app.py", line 1970, in finalize_request
    response = self.process_response(response)
  File "/usr/local/lib/python3.9/site-packages/flask/app.py", line 2267, in process_response
    response = handler(response)
  File "/home/server/app.py", line 160, in after_request
    refresh_token = request.args['refresh_token']
  File "/usr/local/lib/python3.9/site-packages/werkzeug/datastructures.py", line 442, in __getitem__
    raise exceptions.BadRequestKeyError(key)
werkzeug.exceptions.BadRequestKeyError: 400 Bad Request: The browser (or proxy) sent a request that this server could not understand.
2020-11-09 05:55:00,607 - app - ERROR - ('---------------------------------每一个请求之后运行，即使遇到了异常', <BadRequestKeyError '400: Bad Request'>)
2020-11-09 05:56:55,623 - app - ERROR - Exception on /get_user_info [GET]
Traceback (most recent call last):
  File "/usr/local/lib/python3.9/site-packages/flask/app.py", line 2447, in wsgi_app
    response = self.full_dispatch_request()
  File "/usr/local/lib/python3.9/site-packages/flask/app.py", line 1953, in full_dispatch_request
    return self.finalize_request(rv)
  File "/usr/local/lib/python3.9/site-packages/flask/app.py", line 1970, in finalize_request
    response = self.process_response(response)
  File "/usr/local/lib/python3.9/site-packages/flask/app.py", line 2267, in process_response
    response = handler(response)
  File "/home/server/app.py", line 160, in after_request
    refresh_token = request.args['refresh_token']
  File "/usr/local/lib/python3.9/site-packages/werkzeug/datastructures.py", line 442, in __getitem__
    raise exceptions.BadRequestKeyError(key)
werkzeug.exceptions.BadRequestKeyError: 400 Bad Request: The browser (or proxy) sent a request that this server could not understand.
2020-11-09 05:56:55,623 - app - ERROR - Request finalizing failed with an error while handling an error
Traceback (most recent call last):
  File "/usr/local/lib/python3.9/site-packages/flask/app.py", line 2447, in wsgi_app
    response = self.full_dispatch_request()
  File "/usr/local/lib/python3.9/site-packages/flask/app.py", line 1953, in full_dispatch_request
    return self.finalize_request(rv)
  File "/usr/local/lib/python3.9/site-packages/flask/app.py", line 1970, in finalize_request
    response = self.process_response(response)
  File "/usr/local/lib/python3.9/site-packages/flask/app.py", line 2267, in process_response
    response = handler(response)
  File "/home/server/app.py", line 160, in after_request
    refresh_token = request.args['refresh_token']
  File "/usr/local/lib/python3.9/site-packages/werkzeug/datastructures.py", line 442, in __getitem__
    raise exceptions.BadRequestKeyError(key)
werkzeug.exceptions.BadRequestKeyError: 400 Bad Request: The browser (or proxy) sent a request that this server could not understand.

During handling of the above exception, another exception occurred:

Traceback (most recent call last):
  File "/usr/local/lib/python3.9/site-packages/flask/app.py", line 1970, in finalize_request
    response = self.process_response(response)
  File "/usr/local/lib/python3.9/site-packages/flask/app.py", line 2267, in process_response
    response = handler(response)
  File "/home/server/app.py", line 160, in after_request
    refresh_token = request.args['refresh_token']
  File "/usr/local/lib/python3.9/site-packages/werkzeug/datastructures.py", line 442, in __getitem__
    raise exceptions.BadRequestKeyError(key)
werkzeug.exceptions.BadRequestKeyError: 400 Bad Request: The browser (or proxy) sent a request that this server could not understand.
2020-11-09 05:56:55,624 - app - ERROR - ('---------------------------------每一个请求之后运行，即使遇到了异常', <BadRequestKeyError '400: Bad Request'>)
2020-11-09 06:02:53,590 - app - ERROR - Exception on /get_user_info [GET]
Traceback (most recent call last):
  File "/usr/local/lib/python3.9/site-packages/flask/app.py", line 2447, in wsgi_app
    response = self.full_dispatch_request()
  File "/usr/local/lib/python3.9/site-packages/flask/app.py", line 1952, in full_dispatch_request
    rv = self.handle_user_exception(e)
  File "/usr/local/lib/python3.9/site-packages/flask/app.py", line 1821, in handle_user_exception
    reraise(exc_type, exc_value, tb)
  File "/usr/local/lib/python3.9/site-packages/flask/_compat.py", line 39, in reraise
    raise value
  File "/usr/local/lib/python3.9/site-packages/flask/app.py", line 1948, in full_dispatch_request
    rv = self.preprocess_request()
  File "/usr/local/lib/python3.9/site-packages/flask/app.py", line 2242, in preprocess_request
    rv = func()
  File "/home/server/app.py", line 147, in before_request
    result = refresh_token_and_generate_new()
  File "/home/server/app.py", line 55, in refresh_token_and_generate_new
    refresh_token = request.headers['refresh_token']
  File "/usr/local/lib/python3.9/site-packages/werkzeug/datastructures.py", line 1463, in __getitem__
    return _unicodify_header_value(self.environ["HTTP_" + key])
KeyError: 'HTTP_REFRESH_TOKEN'
2020-11-09 06:02:53,592 - app - ERROR - Request finalizing failed with an error while handling an error
Traceback (most recent call last):
  File "/usr/local/lib/python3.9/site-packages/flask/app.py", line 2447, in wsgi_app
    response = self.full_dispatch_request()
  File "/usr/local/lib/python3.9/site-packages/flask/app.py", line 1952, in full_dispatch_request
    rv = self.handle_user_exception(e)
  File "/usr/local/lib/python3.9/site-packages/flask/app.py", line 1821, in handle_user_exception
    reraise(exc_type, exc_value, tb)
  File "/usr/local/lib/python3.9/site-packages/flask/_compat.py", line 39, in reraise
    raise value
  File "/usr/local/lib/python3.9/site-packages/flask/app.py", line 1948, in full_dispatch_request
    rv = self.preprocess_request()
  File "/usr/local/lib/python3.9/site-packages/flask/app.py", line 2242, in preprocess_request
    rv = func()
  File "/home/server/app.py", line 147, in before_request
    result = refresh_token_and_generate_new()
  File "/home/server/app.py", line 55, in refresh_token_and_generate_new
    refresh_token = request.headers['refresh_token']
  File "/usr/local/lib/python3.9/site-packages/werkzeug/datastructures.py", line 1463, in __getitem__
    return _unicodify_header_value(self.environ["HTTP_" + key])
KeyError: 'HTTP_REFRESH_TOKEN'

During handling of the above exception, another exception occurred:

Traceback (most recent call last):
  File "/usr/local/lib/python3.9/site-packages/flask/app.py", line 1970, in finalize_request
    response = self.process_response(response)
  File "/usr/local/lib/python3.9/site-packages/flask/app.py", line 2267, in process_response
    response = handler(response)
  File "/home/server/app.py", line 160, in after_request
    refresh_token = request.headers['refresh_token']
  File "/usr/local/lib/python3.9/site-packages/werkzeug/datastructures.py", line 1463, in __getitem__
    return _unicodify_header_value(self.environ["HTTP_" + key])
KeyError: 'HTTP_REFRESH_TOKEN'
2020-11-09 06:02:53,592 - app - ERROR - ('---------------------------------每一个请求之后运行，即使遇到了异常', KeyError('HTTP_REFRESH_TOKEN'))
2020-11-09 06:17:08,214 - app - ERROR - Exception on /get_user_info [GET]
Traceback (most recent call last):
  File "/usr/local/lib/python3.9/site-packages/flask/app.py", line 2447, in wsgi_app
    response = self.full_dispatch_request()
  File "/usr/local/lib/python3.9/site-packages/flask/app.py", line 1952, in full_dispatch_request
    rv = self.handle_user_exception(e)
  File "/usr/local/lib/python3.9/site-packages/flask/app.py", line 1821, in handle_user_exception
    reraise(exc_type, exc_value, tb)
  File "/usr/local/lib/python3.9/site-packages/flask/_compat.py", line 39, in reraise
    raise value
  File "/usr/local/lib/python3.9/site-packages/flask/app.py", line 1948, in full_dispatch_request
    rv = self.preprocess_request()
  File "/usr/local/lib/python3.9/site-packages/flask/app.py", line 2242, in preprocess_request
    rv = func()
  File "/home/server/app.py", line 149, in before_request
    result = refresh_token_and_generate_new()
  File "/home/server/app.py", line 57, in refresh_token_and_generate_new
    refresh_token = request.headers['refresh_token']
  File "/usr/local/lib/python3.9/site-packages/werkzeug/datastructures.py", line 1463, in __getitem__
    return _unicodify_header_value(self.environ["HTTP_" + key])
KeyError: 'HTTP_REFRESH_TOKEN'
2020-11-09 06:17:08,215 - app - ERROR - Request finalizing failed with an error while handling an error
Traceback (most recent call last):
  File "/usr/local/lib/python3.9/site-packages/flask/app.py", line 2447, in wsgi_app
    response = self.full_dispatch_request()
  File "/usr/local/lib/python3.9/site-packages/flask/app.py", line 1952, in full_dispatch_request
    rv = self.handle_user_exception(e)
  File "/usr/local/lib/python3.9/site-packages/flask/app.py", line 1821, in handle_user_exception
    reraise(exc_type, exc_value, tb)
  File "/usr/local/lib/python3.9/site-packages/flask/_compat.py", line 39, in reraise
    raise value
  File "/usr/local/lib/python3.9/site-packages/flask/app.py", line 1948, in full_dispatch_request
    rv = self.preprocess_request()
  File "/usr/local/lib/python3.9/site-packages/flask/app.py", line 2242, in preprocess_request
    rv = func()
  File "/home/server/app.py", line 149, in before_request
    result = refresh_token_and_generate_new()
  File "/home/server/app.py", line 57, in refresh_token_and_generate_new
    refresh_token = request.headers['refresh_token']
  File "/usr/local/lib/python3.9/site-packages/werkzeug/datastructures.py", line 1463, in __getitem__
    return _unicodify_header_value(self.environ["HTTP_" + key])
KeyError: 'HTTP_REFRESH_TOKEN'

During handling of the above exception, another exception occurred:

Traceback (most recent call last):
  File "/usr/local/lib/python3.9/site-packages/flask/app.py", line 1970, in finalize_request
    response = self.process_response(response)
  File "/usr/local/lib/python3.9/site-packages/flask/app.py", line 2267, in process_response
    response = handler(response)
  File "/home/server/app.py", line 162, in after_request
    refresh_token = request.headers['refresh_token']
  File "/usr/local/lib/python3.9/site-packages/werkzeug/datastructures.py", line 1463, in __getitem__
    return _unicodify_header_value(self.environ["HTTP_" + key])
KeyError: 'HTTP_REFRESH_TOKEN'
2020-11-09 06:17:08,215 - app - ERROR - ('---------------------------------每一个请求之后运行，即使遇到了异常', KeyError('HTTP_REFRESH_TOKEN'))
2020-11-09 06:21:49,714 - app - ERROR - Exception on /get_user_info [GET]
Traceback (most recent call last):
  File "/usr/local/lib/python3.9/site-packages/flask/app.py", line 2447, in wsgi_app
    response = self.full_dispatch_request()
  File "/usr/local/lib/python3.9/site-packages/flask/app.py", line 1952, in full_dispatch_request
    rv = self.handle_user_exception(e)
  File "/usr/local/lib/python3.9/site-packages/flask/app.py", line 1821, in handle_user_exception
    reraise(exc_type, exc_value, tb)
  File "/usr/local/lib/python3.9/site-packages/flask/_compat.py", line 39, in reraise
    raise value
  File "/usr/local/lib/python3.9/site-packages/flask/app.py", line 1948, in full_dispatch_request
    rv = self.preprocess_request()
  File "/usr/local/lib/python3.9/site-packages/flask/app.py", line 2242, in preprocess_request
    rv = func()
  File "/home/server/app.py", line 149, in before_request
    result = refresh_token_and_generate_new()
  File "/home/server/app.py", line 57, in refresh_token_and_generate_new
    refresh_token = request.headers['refresh_token']
  File "/usr/local/lib/python3.9/site-packages/werkzeug/datastructures.py", line 1463, in __getitem__
    return _unicodify_header_value(self.environ["HTTP_" + key])
KeyError: 'HTTP_REFRESH_TOKEN'
2020-11-09 06:21:49,714 - app - ERROR - Request finalizing failed with an error while handling an error
Traceback (most recent call last):
  File "/usr/local/lib/python3.9/site-packages/flask/app.py", line 2447, in wsgi_app
    response = self.full_dispatch_request()
  File "/usr/local/lib/python3.9/site-packages/flask/app.py", line 1952, in full_dispatch_request
    rv = self.handle_user_exception(e)
  File "/usr/local/lib/python3.9/site-packages/flask/app.py", line 1821, in handle_user_exception
    reraise(exc_type, exc_value, tb)
  File "/usr/local/lib/python3.9/site-packages/flask/_compat.py", line 39, in reraise
    raise value
  File "/usr/local/lib/python3.9/site-packages/flask/app.py", line 1948, in full_dispatch_request
    rv = self.preprocess_request()
  File "/usr/local/lib/python3.9/site-packages/flask/app.py", line 2242, in preprocess_request
    rv = func()
  File "/home/server/app.py", line 149, in before_request
    result = refresh_token_and_generate_new()
  File "/home/server/app.py", line 57, in refresh_token_and_generate_new
    refresh_token = request.headers['refresh_token']
  File "/usr/local/lib/python3.9/site-packages/werkzeug/datastructures.py", line 1463, in __getitem__
    return _unicodify_header_value(self.environ["HTTP_" + key])
KeyError: 'HTTP_REFRESH_TOKEN'

During handling of the above exception, another exception occurred:

Traceback (most recent call last):
  File "/usr/local/lib/python3.9/site-packages/flask/app.py", line 1970, in finalize_request
    response = self.process_response(response)
  File "/usr/local/lib/python3.9/site-packages/flask/app.py", line 2267, in process_response
    response = handler(response)
  File "/home/server/app.py", line 162, in after_request
    refresh_token = request.headers['refresh_token']
  File "/usr/local/lib/python3.9/site-packages/werkzeug/datastructures.py", line 1463, in __getitem__
    return _unicodify_header_value(self.environ["HTTP_" + key])
KeyError: 'HTTP_REFRESH_TOKEN'
2020-11-09 06:21:49,715 - app - ERROR - ('---------------------------------每一个请求之后运行，即使遇到了异常', KeyError('HTTP_REFRESH_TOKEN'))
2020-11-09 08:44:42,057 - app - ERROR - Exception on /login [GET]
Traceback (most recent call last):
  File "/usr/local/lib/python3.9/site-packages/flask/app.py", line 2447, in wsgi_app
    response = self.full_dispatch_request()
  File "/usr/local/lib/python3.9/site-packages/flask/app.py", line 1952, in full_dispatch_request
    rv = self.handle_user_exception(e)
  File "/usr/local/lib/python3.9/site-packages/flask/app.py", line 1821, in handle_user_exception
    reraise(exc_type, exc_value, tb)
  File "/usr/local/lib/python3.9/site-packages/flask/_compat.py", line 39, in reraise
    raise value
  File "/usr/local/lib/python3.9/site-packages/flask/app.py", line 1950, in full_dispatch_request
    rv = self.dispatch_request()
  File "/usr/local/lib/python3.9/site-packages/flask/app.py", line 1936, in dispatch_request
    return self.view_functions[rule.endpoint](**req.view_args)
  File "/home/server/base/__init__.py", line 164, in login
    cursor.execute(f'SELECT id,pwd FROM "user" WHERE account = {account}')
psycopg2.errors.UndefinedColumn: column "fgh" does not exist
LINE 1: SELECT id,pwd FROM "user" WHERE account = fgh
                                                  ^

2020-11-09 08:44:42,060 - app - ERROR - ('---------------------------------每一个请求之后运行，即使遇到了异常', UndefinedColumn('column "fgh" does not exist\nLINE 1: SELECT id,pwd FROM "user" WHERE account = fgh\n                                                  ^\n'))
2020-11-10 01:24:42,945 - app - ERROR - Exception on /get_vf_code [GET]
Traceback (most recent call last):
  File "/usr/local/lib/python3.9/site-packages/flask/app.py", line 2447, in wsgi_app
    response = self.full_dispatch_request()
  File "/usr/local/lib/python3.9/site-packages/flask/app.py", line 1952, in full_dispatch_request
    rv = self.handle_user_exception(e)
  File "/usr/local/lib/python3.9/site-packages/flask/app.py", line 1821, in handle_user_exception
    reraise(exc_type, exc_value, tb)
  File "/usr/local/lib/python3.9/site-packages/flask/_compat.py", line 39, in reraise
    raise value
  File "/usr/local/lib/python3.9/site-packages/flask/app.py", line 1950, in full_dispatch_request
    rv = self.dispatch_request()
  File "/usr/local/lib/python3.9/site-packages/flask/app.py", line 1936, in dispatch_request
    return self.view_functions[rule.endpoint](**req.view_args)
  File "/home/server/base/__init__.py", line 58, in get_vf_code
    send_email(email, 'something验证码', f'您的验证码是：{code}，10分钟内有效')
  File "/home/server/pub.py", line 34, in send_email
    mail.send(msg)
  File "/usr/local/lib/python3.9/site-packages/flask_mail.py", line 492, in send
    message.send(connection)
  File "/usr/local/lib/python3.9/site-packages/flask_mail.py", line 427, in send
    connection.send(self)
  File "/usr/local/lib/python3.9/site-packages/flask_mail.py", line 188, in send
    self.host.sendmail(sanitize_address(envelope_from or message.sender),
  File "/usr/local/lib/python3.9/smtplib.py", line 871, in sendmail
    raise SMTPSenderRefused(code, resp, from_addr)
smtplib.SMTPSenderRefused: (502, b'Invalid input from 47.93.232.107 to newxmesmtplogicsvrszc9.qq.com.', 'something')
2020-11-10 01:24:42,951 - app - ERROR - ('---------------------------------每一个请求之后运行，即使遇到了异常', SMTPSenderRefused(502, b'Invalid input from 47.93.232.107 to newxmesmtplogicsvrszc9.qq.com.', 'something'))
2020-11-10 01:26:47,854 - app - ERROR - Exception on /get_vf_code [GET]
Traceback (most recent call last):
  File "/usr/local/lib/python3.9/site-packages/flask/app.py", line 2447, in wsgi_app
    response = self.full_dispatch_request()
  File "/usr/local/lib/python3.9/site-packages/flask/app.py", line 1952, in full_dispatch_request
    rv = self.handle_user_exception(e)
  File "/usr/local/lib/python3.9/site-packages/flask/app.py", line 1821, in handle_user_exception
    reraise(exc_type, exc_value, tb)
  File "/usr/local/lib/python3.9/site-packages/flask/_compat.py", line 39, in reraise
    raise value
  File "/usr/local/lib/python3.9/site-packages/flask/app.py", line 1950, in full_dispatch_request
    rv = self.dispatch_request()
  File "/usr/local/lib/python3.9/site-packages/flask/app.py", line 1936, in dispatch_request
    return self.view_functions[rule.endpoint](**req.view_args)
  File "/home/server/base/__init__.py", line 58, in get_vf_code
    send_email(email, 'something验证码', f'您的验证码是：{code}，10分钟内有效')
  File "/home/server/pub.py", line 34, in send_email
    mail.send(msg)
  File "/usr/local/lib/python3.9/site-packages/flask_mail.py", line 492, in send
    message.send(connection)
  File "/usr/local/lib/python3.9/site-packages/flask_mail.py", line 427, in send
    connection.send(self)
  File "/usr/local/lib/python3.9/site-packages/flask_mail.py", line 188, in send
    self.host.sendmail(sanitize_address(envelope_from or message.sender),
  File "/usr/local/lib/python3.9/smtplib.py", line 871, in sendmail
    raise SMTPSenderRefused(code, resp, from_addr)
smtplib.SMTPSenderRefused: (502, b'Invalid input from 47.93.232.107 to newxmesmtplogicsvrszc7.qq.com.', 'something')
2020-11-10 01:26:47,854 - app - ERROR - ('---------------------------------每一个请求之后运行，即使遇到了异常', SMTPSenderRefused(502, b'Invalid input from 47.93.232.107 to newxmesmtplogicsvrszc7.qq.com.', 'something'))
2020-11-10 01:31:29,080 - app - ERROR - Exception on /get_vf_code [GET]
Traceback (most recent call last):
  File "/usr/local/lib/python3.9/site-packages/flask/app.py", line 2447, in wsgi_app
    response = self.full_dispatch_request()
  File "/usr/local/lib/python3.9/site-packages/flask/app.py", line 1952, in full_dispatch_request
    rv = self.handle_user_exception(e)
  File "/usr/local/lib/python3.9/site-packages/flask/app.py", line 1821, in handle_user_exception
    reraise(exc_type, exc_value, tb)
  File "/usr/local/lib/python3.9/site-packages/flask/_compat.py", line 39, in reraise
    raise value
  File "/usr/local/lib/python3.9/site-packages/flask/app.py", line 1950, in full_dispatch_request
    rv = self.dispatch_request()
  File "/usr/local/lib/python3.9/site-packages/flask/app.py", line 1936, in dispatch_request
    return self.view_functions[rule.endpoint](**req.view_args)
  File "/home/server/base/__init__.py", line 58, in get_vf_code
    send_email(email, 'something验证码', f'您的验证码是：{code}，10分钟内有效')
  File "/home/server/pub.py", line 34, in send_email
    mail.send(msg)
  File "/usr/local/lib/python3.9/site-packages/flask_mail.py", line 492, in send
    message.send(connection)
  File "/usr/local/lib/python3.9/site-packages/flask_mail.py", line 427, in send
    connection.send(self)
  File "/usr/local/lib/python3.9/site-packages/flask_mail.py", line 188, in send
    self.host.sendmail(sanitize_address(envelope_from or message.sender),
  File "/usr/local/lib/python3.9/smtplib.py", line 871, in sendmail
    raise SMTPSenderRefused(code, resp, from_addr)
smtplib.SMTPSenderRefused: (503, b'Error: need EHLO and AUTH first !', 'jessewee@qq.com')
2020-11-10 01:31:29,082 - app - ERROR - ('---------------------------------每一个请求之后运行，即使遇到了异常', SMTPSenderRefused(503, b'Error: need EHLO and AUTH first !', 'jessewee@qq.com'))
2020-11-10 01:48:02,765 - app - ERROR - Exception on /get_vf_code [GET]
Traceback (most recent call last):
  File "/usr/local/lib/python3.9/site-packages/flask/app.py", line 2447, in wsgi_app
    response = self.full_dispatch_request()
  File "/usr/local/lib/python3.9/site-packages/flask/app.py", line 1952, in full_dispatch_request
    rv = self.handle_user_exception(e)
  File "/usr/local/lib/python3.9/site-packages/flask/app.py", line 1821, in handle_user_exception
    reraise(exc_type, exc_value, tb)
  File "/usr/local/lib/python3.9/site-packages/flask/_compat.py", line 39, in reraise
    raise value
  File "/usr/local/lib/python3.9/site-packages/flask/app.py", line 1948, in full_dispatch_request
    rv = self.preprocess_request()
  File "/usr/local/lib/python3.9/site-packages/flask/app.py", line 2242, in preprocess_request
    rv = func()
  File "/home/server/app.py", line 114, in before_request
    for k, v in request.values:
ValueError: too many values to unpack (expected 2)
2020-11-10 01:48:02,768 - app - ERROR - ('---------------------------------每一个请求之后运行，即使遇到了异常', ValueError('too many values to unpack (expected 2)'))
2020-11-10 01:51:45,784 - app - ERROR - Exception on /register [POST]
Traceback (most recent call last):
  File "/usr/local/lib/python3.9/site-packages/flask/app.py", line 2447, in wsgi_app
    response = self.full_dispatch_request()
  File "/usr/local/lib/python3.9/site-packages/flask/app.py", line 1952, in full_dispatch_request
    rv = self.handle_user_exception(e)
  File "/usr/local/lib/python3.9/site-packages/flask/app.py", line 1821, in handle_user_exception
    reraise(exc_type, exc_value, tb)
  File "/usr/local/lib/python3.9/site-packages/flask/_compat.py", line 39, in reraise
    raise value
  File "/usr/local/lib/python3.9/site-packages/flask/app.py", line 1950, in full_dispatch_request
    rv = self.dispatch_request()
  File "/usr/local/lib/python3.9/site-packages/flask/app.py", line 1936, in dispatch_request
    return self.view_functions[rule.endpoint](**req.view_args)
  File "/home/server/base/__init__.py", line 71, in register
    cursor.execute(f'''SELECT id FROM user WHERE account = '{account}' ''')
psycopg2.errors.UndefinedColumn: column "id" does not exist
LINE 1: SELECT id FROM user WHERE account = 'sdfsdfsf' 
               ^

2020-11-10 01:51:45,785 - app - ERROR - ('---------------------------------每一个请求之后运行，即使遇到了异常', UndefinedColumn('column "id" does not exist\nLINE 1: SELECT id FROM user WHERE account = \'sdfsdfsf\' \n               ^\n'))
2020-11-10 03:11:39,678 - app - ERROR - ('---------------------------------每一个请求之后运行，即使遇到了异常', AttributeError("'NoneType' object has no attribute 'strip'"))
2020-11-10 03:12:07,182 - app - ERROR - ('---------------------------------每一个请求之后运行，即使遇到了异常', AttributeError("'NoneType' object has no attribute 'strip'"))
2020-11-10 03:15:42,653 - app - ERROR - ('---------------------------------每一个请求之后运行，即使遇到了异常', TypeError('Object of type datetime is not JSON serializable'))
2020-11-10 07:48:24,990 - app - ERROR - ('---------------------------------每一个请求之后运行，即使遇到了异常', <BadRequestKeyError '400: Bad Request'>)
